<mujoco model="T1">
  <compiler angle="radian" meshdir="" autolimits="true"/>
  <!-- meshdir=""意味着网格文件和 XML 在同一个文件夹，radian是弧度 -->
  <option integrator="implicitfast"/>
  <asset>
    <material name="light_gray" rgba="0.76 0.76 0.76 1"/>
    <!-- 图形渲染用的视觉属性 -->
    <material name="medium_gray" rgba="0.4 0.4 0.4 1"/>
    <material name="LightGrey" specular="0.9" shininess="0.9" rgba="0.4 0.4 0.4 1.0"/>
    <material name="Purple" specular="0.9" shininess="0.9" rgba="0.58 0.42 0.58 1.0"/>
    <material name="Black" specular="0.9" shininess="0.9" rgba="0.1 0.1 0.1 1.0"/>
    <texture type="skybox" builtin="gradient" rgb1=".3 .5 .7" rgb2="0 0 0" width="32" height="512"/>
    <!-- 贴图背景 -->
    <texture name="body" type="cube" builtin="flat" mark="cross" width="128" height="128" rgb1="0.8 0.6 0.4" rgb2="0.8 0.6 0.4" markrgb="1 1 1" random="0.01"/>
    <material name="body" texture="body" texuniform="true" rgba="0.8 0.6 .4 1"/>
    <texture name="grid" type="2d" builtin="checker" width="512" height="512" rgb1=".1 .2 .3" rgb2=".2 .3 .4"/>
    <material name="grid" texture="grid" texrepeat="1 1" texuniform="true" reflectance="0.02"/>
    <mesh name="Trunk" file="./meshes/Trunk.STL"/>
    <mesh name="H1" file="./meshes/H1.STL"/>
    <mesh name="H2" file="./meshes/H2.STL"/>
    <mesh name="AL1" file="./meshes/AL1.STL"/>
    <mesh name="AL2" file="./meshes/AL2.STL"/>
    <mesh name="AL3" file="./meshes/AL3.STL"/>
    <mesh name="AL4" file="./meshes/AL4.STL"/>
    <mesh name="AL5" file="./meshes/AL5.STL"/>
    <mesh name="AL6" file="./meshes/AL6.STL"/>
    <mesh name="AL7" file="./meshes/AL7.STL"/>
    <mesh name="AR1" file="./meshes/AR1.STL"/>
    <mesh name="AR2" file="./meshes/AR2.STL"/>
    <mesh name="AR3" file="./meshes/AR3.STL"/>
    <mesh name="AR4" file="./meshes/AR4.STL"/>
    <mesh name="AR5" file="./meshes/AR5.STL"/>
    <mesh name="AR6" file="./meshes/AR6.STL"/>
    <mesh name="AR7" file="./meshes/AR7.STL"/>
    <mesh name="Waist" file="./meshes/Waist.STL"/>
    <mesh name="Hip_Pitch_Left" file="./meshes/Hip_Pitch_Left.STL"/>
    <mesh name="Hip_Roll_Left" file="./meshes/Hip_Roll_Left.STL"/>
    <mesh name="Hip_Yaw_Left" file="./meshes/Hip_Yaw_Left.STL"/>
    <mesh name="Shank_Left" file="./meshes/Shank_Left.STL"/>
    <mesh name="Ankle_Cross_Left" file="./meshes/Ankle_Cross_Left.STL"/>
    <mesh name="left_foot_link" file="./meshes/left_foot_link.STL"/>
    <mesh name="Hip_Pitch_Right" file="./meshes/Hip_Pitch_Right.STL"/>
    <mesh name="Hip_Roll_Right" file="./meshes/Hip_Roll_Right.STL"/>
    <mesh name="Hip_Yaw_Right" file="./meshes/Hip_Yaw_Right.STL"/>
    <mesh name="Shank_Right" file="./meshes/Shank_Right.STL"/>
    <mesh name="Ankle_Cross_Right" file="./meshes/Ankle_Cross_Right.STL"/>
    <mesh name="right_foot_link" file="./meshes/right_foot_link.STL"/>
  </asset>

  <!-- Removed nested 'visual' and 'collision' defaults -->
  <default>
    
    <geom material="medium_gray"/>
    <site rgba="1 0 0 1" size="0.01" group="5"/>
    <joint frictionloss="0.2" armature="0.05" damping="1.0"/>
      <!-- The following nested defaults are removed to comply with robosuite -->
      <!--
      <default class="visual">
        <geom type="mesh" contype="0" conaffinity="0" group="2"/>
      </default>
      <default class="collision">
        <geom group="3"/>
      </default>
      -->
    <default class="heavy_joint">
        <joint damping="5.0" armature="0.05"/>
    </default>
  </default>

  <worldbody>
    <light pos="1 0 3.5" dir="0 0 -1" directional="true"/>
    <geom name="floor" pos="0 0 -0.97" size="1 1 0.02" type="plane" material="grid"/>

    <body name="Trunk" pos="0 0 .7" >
      <freejoint/>
      <inertial pos="0.0551365 -1.42058e-06 0.105062" quat="0.99996 1.40561e-05 -0.00899532 -1.39249e-05" mass="11.7" diaginertia="0.0915404 0.0767787 0.0556055"/>
      <site name="imu"/>
      <!-- Replaced class="visual" with explicit attributes -->
      <geom type="mesh" contype="0" conaffinity="0" group="1" material="light_gray" mesh="Trunk"/>
      <!-- Replaced class="collision" with explicit attributes -->
      <geom size="0.075 0.1 0.15" pos="0.06 0 0.12" type="box" group="1" contype="1" conaffinity="1"/>

      <body name="H1" pos="0.0625 0 0.243">
        <inertial pos="-0.000508 -0.001403 0.057432" quat="0.763881 -0.0132172 0.00173419 0.645219" mass="0.44391" diaginertia="0.000241549 0.00022351 0.000149941"/>
        <joint name="head_AAHead_yaw" axis="0 0 1" range="-1.57 1.57" actuatorfrcrange="-7 7"/>
        <geom type="mesh" contype="0" conaffinity="0" group="1" mesh="H1"/>
        <body name="H2" pos="0 0 0.06185">
          <inertial pos="0.007802 0.001262 0.098631" quat="0.988453 0.106172 -0.0745686 -0.0782786" mass="0.631019" diaginertia="0.00203553 0.00192467 0.00172381"/>
          <joint name="head_Head_pitch" axis="0 1 0" range="-0.35 1.22" actuatorfrcrange="-7 7"/>
          <geom type="mesh" contype="0" conaffinity="0" group="1" mesh="H2"/>
          <geom size="0.08" pos="0.01 0 0.11" type="sphere" group="1" contype="1" conaffinity="1"/>
        </body>
      </body>

      <!-- LEFT ARM -->
      <body name="AL1" pos="0.0575 0.1063 0.219" quat="1 0 0.000440565 0">
        <site name="left_center" pos="0 0 0" size="0.01" rgba="1 0.3 0.3 1" group="2" />
        <inertial pos="-0.000677 0.044974 0" quat="0.50423 0.495734 -0.50423 0.495734" mass="0.53" diaginertia="0.001367 0.00129329 0.000292711"/>
        <joint name="Left_Shoulder_Pitch" pos="0 0 0" axis="0 1 0" range="-3.29 1.18"/>
        <geom type="mesh" contype="0" conaffinity="0" group="1" density="0" rgba="0.76 0.76 0.76 0.2" mesh="AL1"/>
        <body name="AL2" pos="0 0.047 0">
          <inertial pos="0.003862 0.037976 0" quat="0.487991 0.511727 0.487991 0.511727" mass="0.16" diaginertia="0.000401 0.00034538 0.00017662"/>
          <joint name="Left_Shoulder_Roll" pos="0 0 0" axis="1 0 0" range="-1.577 1.7055"/>
          <geom type="mesh" contype="0" conaffinity="0" group="1" density="0" rgba="0.4 0.4 0.4 0.3" mesh="AL2"/>
          <body name="AL3" pos="0.00025 0.0605 0">
            <inertial pos="0 0.085353 -9.9e-05" quat="0.70641 0.707803 0 0" mass="1.02" diaginertia="0.012869 0.012798 0.000620953"/>
            <joint name="Left_Elbow_Pitch" pos="0 0 0" axis="0 1 0" range="-2.234 2.234"/>
            <geom type="mesh" contype="0" conaffinity="0" group="1" density="0" rgba="0.4 0.4 0.4 0.3" mesh="AL3"/>
            <body name="AL4" pos="0 0.1471 0">
              <inertial pos="-0.00046851 0.062372 0.0015178" quat="0.708114 0.706086 -0.00272503 -0.00309075" mass="0.557" diaginertia="0.0016731 0.00160801 0.00021389"/>
              <joint name="Left_Elbow_Yaw" pos="0 0 0" axis="0 0 1" range="-2.1402 1.6844"/>
              <geom type="mesh" contype="1" conaffinity="1" group="1" density="0" rgba="0.75294 0.75294 0.75294 1" mesh="AL4"/>
              <body name="AL5" pos="0 0.105 0.00025">
                <inertial pos="-3.8402e-05 0.036076 0.0056711" quat="0.763252 0.646101 0 0" mass="0.43402" diaginertia="0.000823 0.000801406 0.000199594"/>
                <joint name="Left_Wrist_Pitch" pos="0 0 0" axis="0 1 0" range="-2.5821 2.5821"/>
                <geom type="mesh" contype="1" conaffinity="1" group="1" density="0" rgba="0.75294 0.75294 0.75294 1" mesh="AL5"/>
                <body name="AL6" pos="0 0.042 0">
                  <inertial pos="-0.00072939 0.056578 -0.0056257" quat="0.701498 0.712537 0.00305334 -0.0134832" mass="0.47922" diaginertia="0.00117124 0.00113821 0.000165544"/>
                  <joint name="Left_Wrist_Yaw" pos="0 0 0" axis="0 0 1" range="-1.8185 1.4261"/>
                  <geom type="mesh" contype="1" conaffinity="1" group="1" density="0" rgba="0.75294 0.75294 0.75294 1" mesh="AL6"/>
                  <body name="AL7" pos="0.00475 0.07 0.0015">
                    <inertial pos="-0.0067917 0.06373 0.011867" quat="0.486792 0.512522 -0.512399 0.487649" mass="0.30603" diaginertia="0.00244446 0.002302 0.000301541"/>
                    <joint name="Left_Hand_Roll" pos="0 0 0" axis="1 0 0" range="-0.758 1.4285"/>
                    <geom type="mesh" contype="1" conaffinity="1" group="1" density="0" rgba="0.75294 0.75294 0.75294 1" mesh="AL7"/>
                    <body name="left_tip" pos="0 0.15 0">
                      <inertial pos="0 0 0" mass="1e-6" diaginertia="1e-6 1e-6 1e-6"/> 
                      <site name="left_tip_visual" pos="0 0 0" size="0.01" rgba="1 0 0 1"/>
                    </body>
                  </body>
                </body>
              </body>
            </body>
          </body>
        </body>
      </body>

      <!-- RIGHT ARM -->
      <body name="AR1" pos="0.0575 -0.1063 0.219" quat="1 0 0.000440565 0">
      	<site name="right_center" pos="0 0 0" size="0.01" rgba="1 0.3 0.3 1" group="2" />
        <inertial pos="-0.000677 -0.044974 0" quat="0.50423 0.495734 -0.50423 0.495734" mass="0.53" diaginertia="0.001367 0.00129329 0.000292711"/>
        <joint name="Right_Shoulder_Pitch" pos="0 0 0" axis="0 1 0" range="-3.29 1.1868"/>
        <geom type="mesh" contype="0" conaffinity="0" group="1" density="0" rgba="0.76 0.76 0.76 0.2" mesh="AR1"/>
        <body name="AR2" pos="0 -0.047 0">
          <inertial pos="0.003862 -0.037976 0" quat="0.511727 0.487991 -0.511727 0.487991" mass="0.16" diaginertia="0.000401 0.00034538 0.00017662"/>
          <joint name="Right_Shoulder_Roll" pos="0 0 0" axis="1 0 0" range="-1.7055 1.577"/>
          <geom type="mesh" contype="0" conaffinity="0" group="1" density="0" rgba="0.4 0.4 0.4 0.3" mesh="AR2"/>
          <body name="AR3" pos="0.00025 -0.0605 0">
            <inertial pos="0 -0.085353 -9.9e-05" quat="0.707803 0.70641 0 0" mass="1.02" diaginertia="0.012869 0.012798 0.000620953"/>
            <joint name="Right_Elbow_Pitch" pos="0 0 0" axis="0 1 0" range="-2.234 2.234"/>
            <geom type="mesh" contype="0" conaffinity="0" group="1" density="0" rgba="0.4 0.4 0.4 0.3" mesh="AR3"/>
            <body name="AR4" pos="0 -0.1471 0">
              <inertial pos="-0.0004573 -0.067734 0.0017465" quat="0.706214 0.70799 0.00258227 0.0022281" mass="0.557" diaginertia="0.0022921 0.00222301 0.000233892"/>
              <joint name="Right_Elbow_Yaw" pos="0 0 0" axis="0 0 1" range="-1.6844 2.1402"/>
              <geom type="mesh" contype="1" conaffinity="1" group="1" density="0" rgba="0.75294 0.75294 0.75294 1" mesh="AR4"/>
              <body name="AR5" pos="0 -0.105 0.00025">
                <inertial pos="3.7355e-05 -0.035638 0.0053147" quat="0.648697 0.761046 0 0" mass="0.43402" diaginertia="0.000836 0.000812239 0.000204761"/>
                <joint name="Right_Wrist_Pitch" pos="0 0 0" axis="0 1 0" range="-2.5821 2.5821"/>
                <geom type="mesh" contype="1" conaffinity="1" group="1" density="0" rgba="0.75294 0.75294 0.75294 1" mesh="AR5"/>
                <body name="AR6" pos="0 -0.042 0">
                  <inertial pos="-0.0011437 -0.056205 -0.0056621" quat="0.711908 0.702081 0.0164127 -0.000464544" mass="0.47922" diaginertia="0.00123856 0.00121017 0.000181264"/>
                  <joint name="Right_Wrist_Yaw" pos="0 0 0" axis="0 0 1" range="-1.4261 1.8185"/>
                  <geom type="mesh" contype="1" conaffinity="1" group="1" density="0" rgba="0.75294 0.75294 0.75294 1" mesh="AR6"/>
                  <body name="AR7" pos="0.00475 -0.07 0.0015">
                    <inertial pos="-0.0047758 -0.064411 0.011992" quat="0.488328 0.51175 -0.511877 0.487473" mass="0.30603" diaginertia="0.00242288 0.002287 0.000287116"/>
                    <joint name="Right_Hand_Roll" pos="0 0 0" axis="1 0 0" range="-1.4285 0.758"/>
                    <geom type="mesh" contype="1" conaffinity="1" group="1" density="0" rgba="0.75294 0.75294 0.75294 1" mesh="AR7"/>
                    <body name="right_tip" pos="0 -0.15 0">
                      <inertial pos="0 0 0" mass="1e-6" diaginertia="1e-6 1e-6 1e-6"/> <site name="right_tip_site" pos="0 0 0" size="0.01" rgba="1 0 0 1"/>
                    </body>
                  </body>
                </body>
              </body>
            </body>
          </body>
        </body>
      </body>

      <!-- WAIST AND LEGS -->
      <body name="Waist" pos="0.0625 0 -0.1155">
        <inertial pos="0.002284 3e-06 0.007301" quat="0.983649 0.000360386 -0.180076 0.00269791" mass="2.581" diaginertia="0.00536742 0.005299 0.00474258"/>
        <joint name="torso_Waist" axis="0 0 1" range="-1.57 1.57" actuatorfrcrange="-30 30"/>
        <geom type="mesh" contype="0" conaffinity="0" group="1" mesh="Waist"/>
        
        <!-- LEFT LEG -->
        <body name="Hip_Pitch_Left" pos="0 0.106 0">
          <inertial pos="0.000534 -0.007296 -0.018083" quat="0.975141 0.2211 0.0145808 0.0017406" mass="1.021" diaginertia="0.00180547 0.00145926 0.00125327"/>
          <joint name="leg_Left_Hip_Pitch" axis="0 1 0" range="-1.8 1.57" actuatorfrcrange="-45 45"/>
          <geom type="mesh" contype="0" conaffinity="0" group="1" material="light_gray" mesh="Hip_Pitch_Left"/>
          <body name="Hip_Roll_Left" pos="0 0 -0.02">
            <inertial pos="0.001101 2.4e-05 -0.05375" quat="0.707081 -0.00599604 -0.00599604 0.707081" mass="0.385" diaginertia="0.001743 0.00151729 0.000514712"/>
            <joint name="leg_Left_Hip_Roll" axis="1 0 0" range="-0.2 1.57" actuatorfrcrange="-30 30"/>
            <geom type="mesh" contype="0" conaffinity="0" group="1" mesh="Hip_Roll_Left"/>
            <body name="Hip_Yaw_Left" pos="0 0 -0.081854">
              <inertial pos="-0.007233 0.000206 -0.089184" quat="0.696808 -0.033953 -0.0315708 0.715758" mass="2.166" diaginertia="0.0257334 0.0253024 0.00259215"/>
              <joint name="leg_Left_Hip_Yaw" axis="0 0 1" range="-1 1" actuatorfrcrange="-30 30"/>
              <geom type="mesh" contype="0" conaffinity="0" group="1" mesh="Hip_Yaw_Left"/>
              <geom size="0.05 0.08" type="cylinder" group="1" contype="1" conaffinity="1"/>
              <body name="Shank_Left" pos="-0.014 0 -0.134">
                <inertial pos="-0.006012 0.000259 -0.124318" quat="0.997573 0.00144024 -0.023949 0.0653706" mass="1.73" diaginertia="0.0346951 0.0345375 0.00185844"/>
                <joint name="leg_Left_Knee_Pitch" axis="0 1 0" range="0 2.34" actuatorfrcrange="-60 60"/>
                <geom type="mesh" contype="0" conaffinity="0" group="1" mesh="Shank_Left"/>
                <geom size="0.05 0.075" pos="0 0 -0.12" type="cylinder" group="1" contype="1" conaffinity="1"/>
                <body name="Ankle_Cross_Left" pos="0 0 -0.28">
                  <inertial pos="-0.003722 0 -0.007981" quat="0.443136 0.551027 0.551027 0.443136" mass="0.073" diaginertia="2.9e-05 2.56589e-05 1.13411e-05"/>
                  <joint name="leg_Left_Ankle_Pitch" axis="0 1 0" range="-0.87 0.35" actuatorfrcrange="-20 20"/>
                  <geom type="mesh" contype="0" conaffinity="0" group="1" mesh="Ankle_Cross_Left"/>
                  <body name="left_foot_link" pos="0 0.00025 -0.012">
                    <inertial pos="-0.000249 0 -0.00914" quat="0 0.620755 0 0.784005" mass="0.685" diaginertia="0.00269786 0.002385 0.00218714"/>
                    <joint name="leg_Left_Ankle_Roll" axis="1 0 0" range="-0.44 0.44" actuatorfrcrange="-15 15"/>
                    <geom type="mesh" contype="0" conaffinity="0" group="1" mesh="left_foot_link"/>
                    <geom size="0.1115 0.05 0.015" pos="0.01 0 -0.015" type="box" group="1" contype="1" conaffinity="1"/>
                  </body>
                </body>
              </body>
            </body>
          </body>
        </body>

        <!-- RIGHT LEG -->
        <body name="Hip_Pitch_Right" pos="0 -0.106 0">
          <inertial pos="0.000534 0.007514 -0.018082" quat="0.973446 -0.228403 0.0147148 -0.00419349" mass="1.021" diaginertia="0.00180552 0.0014632 0.00124928"/>
          <joint name="leg_Right_Hip_Pitch" axis="0 1 0" range="-1.8 1.57" actuatorfrcrange="-45 45"/>
          <geom type="mesh" contype="0" conaffinity="0" group="1" material="light_gray" mesh="Hip_Pitch_Right"/>
          <body name="Hip_Roll_Right" pos="0 0 -0.02">
            <inertial pos="0.001099 2.4e-05 -0.053748" quat="0.707081 -0.00599604 -0.00599604 0.707081" mass="0.385" diaginertia="0.001743 0.00151729 0.000514712"/>
            <joint name="leg_Right_Hip_Roll" axis="1 0 0" range="-1.57 0.2" actuatorfrcrange="-30 30"/>
            <geom type="mesh" contype="0" conaffinity="0" group="1" mesh="Hip_Roll_Right"/>
            <body name="Hip_Yaw_Right" pos="0 0 -0.081854">
              <inertial pos="-0.007191 -0.000149 -0.08922" quat="0.714468 -0.0315638 -0.0336391 0.698146" mass="2.17" diaginertia="0.0257623 0.0253298 0.00259389"/>
              <joint name="leg_Right_Hip_Yaw" axis="0 0 1" range="-1 1" actuatorfrcrange="-30 30"/>
              <geom type="mesh" contype="0" conaffinity="0" group="1" mesh="Hip_Yaw_Right"/>
              <geom size="0.05 0.08" type="cylinder" group="1" contype="1" conaffinity="1"/>
              <body name="Shank_Right" pos="-0.014 0 -0.134">
                <inertial pos="-0.005741 -0.000541 -0.122602" quat="0.99926 -0.000580963 -0.023461 -0.0304754" mass="1.79" diaginertia="0.0351717 0.0349574 0.00196589"/>
                <joint name="leg_Right_Knee_Pitch" axis="0 1 0" range="0 2.34" actuatorfrcrange="-60 60"/>
                <geom type="mesh" contype="0" conaffinity="0" group="1" mesh="Shank_Right"/>
                <geom size="0.05 0.075" pos="0 0 -0.12" type="cylinder" group="1" contype="1" conaffinity="1"/>
                <body name="Ankle_Cross_Right" pos="0 0 -0.28">
                  <inertial pos="-0.003722 0 -0.007981" quat="0.443136 0.551027 0.551027 0.443136" mass="0.073" diaginertia="2.9e-05 2.56589e-05 1.13411e-05"/>
                  <joint name="leg_Right_Ankle_Pitch" axis="0 1 0" range="-0.87 0.35" actuatorfrcrange="-20 20"/>
                  <geom type="mesh" contype="0" conaffinity="0" group="1" mesh="Ankle_Cross_Right"/>
                  <body name="right_foot_link" pos="0 -0.00025 -0.012">
                    <inertial pos="-0.000248 0 -0.00914" quat="0 0.620755 0 0.784005" mass="0.685" diaginertia="0.00269786 0.002385 0.00218714"/>
                    <joint name="leg_Right_Ankle_Roll" axis="1 0 0" range="-0.44 0.44" actuatorfrcrange="-15 15"/>
                    <geom type="mesh" contype="0" conaffinity="0" group="1" mesh="right_foot_link"/>
                    <geom size="0.1115 0.05 0.015" pos="0.01 0 -0.015" type="box" group="1" contype="1" conaffinity="1"/>
                  </body>
                </body>
              </body>
            </body>
          </body>
        </body>
      </body>
    </body>
  </worldbody>

<!-- Actuators -->
<actuator>
  <motor ctrllimited="true" ctrlrange="-25 25" joint="torso_Waist" name="act_torso_Waist"/>

  <motor ctrllimited="true" ctrlrange="-7 7" joint="head_AAHead_yaw" name="act_head_AAHead_yaw"/>
  <motor ctrllimited="true" ctrlrange="-7 7" joint="head_Head_pitch" name="act_head_Head_pitch"/>

  <motor ctrllimited="true" ctrlrange="-18 18" joint="Left_Shoulder_Pitch" name="act_Left_Shoulder_Pitch"/>
  <motor ctrllimited="true" ctrlrange="-18 18" joint="Left_Shoulder_Roll" name="act_Left_Shoulder_Roll"/>
  <motor ctrllimited="true" ctrlrange="-18 18" joint="Left_Elbow_Pitch" name="act_Left_Elbow_Pitch"/>
  <motor ctrllimited="true" ctrlrange="-18 18" joint="Left_Elbow_Yaw" name="act_Left_Elbow_Yaw"/>
  <motor ctrllimited="true" ctrlrange="-18 18" joint="Left_Wrist_Pitch" name="act_Left_Wrist_Pitch"/>
  <motor ctrllimited="true" ctrlrange="-18 18" joint="Left_Wrist_Yaw" name="act_Left_Wrist_Yaw"/>
  <motor ctrllimited="true" ctrlrange="-18 18" joint="Left_Hand_Roll" name="act_Left_Hand_Roll"/>

  <motor ctrllimited="true" ctrlrange="-18 18" joint="Right_Shoulder_Pitch" name="act_Right_Shoulder_Pitch"/>
  <motor ctrllimited="true" ctrlrange="-18 18" joint="Right_Shoulder_Roll" name="act_Right_Shoulder_Roll"/>
  <motor ctrllimited="true" ctrlrange="-18 18" joint="Right_Elbow_Pitch" name="act_Right_Elbow_Pitch"/>
  <motor ctrllimited="true" ctrlrange="-18 18" joint="Right_Elbow_Yaw" name="act_Right_Elbow_Yaw"/>
  <motor ctrllimited="true" ctrlrange="-18 18" joint="Right_Wrist_Pitch" name="act_Right_Wrist_Pitch"/>
  <motor ctrllimited="true" ctrlrange="-18 18" joint="Right_Wrist_Yaw" name="act_Right_Wrist_Yaw"/>
  <motor ctrllimited="true" ctrlrange="-18 18" joint="Right_Hand_Roll" name="act_Right_Hand_Roll"/>

  <motor ctrllimited="true" ctrlrange="-45 45" joint="leg_Left_Hip_Pitch" name="act_leg_Left_Hip_Pitch"/>
  <motor ctrllimited="true" ctrlrange="-25 25" joint="leg_Left_Hip_Roll" name="act_leg_Left_Hip_Roll"/>
  <motor ctrllimited="true" ctrlrange="-25 25" joint="leg_Left_Hip_Yaw" name="act_leg_Left_Hip_Yaw"/>
  <motor ctrllimited="true" ctrlrange="-60 60" joint="leg_Left_Knee_Pitch" name="act_leg_Left_Knee_Pitch"/>
  <motor ctrllimited="true" ctrlrange="-24 24" joint="leg_Left_Ankle_Pitch" name="act_leg_Left_Ankle_Pitch"/>
  <motor ctrllimited="true" ctrlrange="-15 15" joint="leg_Left_Ankle_Roll" name="act_leg_Left_Ankle_Roll"/>

  <motor ctrllimited="true" ctrlrange="-45 45" joint="leg_Right_Hip_Pitch" name="act_leg_Right_Hip_Pitch"/>
  <motor ctrllimited="true" ctrlrange="-25 25" joint="leg_Right_Hip_Roll" name="act_leg_Right_Hip_Roll"/>
  <motor ctrllimited="true" ctrlrange="-25 25" joint="leg_Right_Hip_Yaw" name="act_leg_Right_Hip_Yaw"/>
  <motor ctrllimited="true" ctrlrange="-60 60" joint="leg_Right_Knee_Pitch" name="act_leg_Right_Knee_Pitch"/>
  <motor ctrllimited="true" ctrlrange="-24 24" joint="leg_Right_Ankle_Pitch" name="act_leg_Right_Ankle_Pitch"/>
  <motor ctrllimited="true" ctrlrange="-15 15" joint="leg_Right_Ankle_Roll" name="act_leg_Right_Ankle_Roll"/>
</actuator>

</mujoco>